Workbook

Sheet 01_PARÂMETROS
A1: PARÂMETROS — ÂNCORA DE TODAS AS FÓRMULAS DO MOTOR
A2: Todas as abas referenciam esta aba. Altere aqui para propagar ao motor inteiro.
A3: BLOCO A — FÓRMULA IC (pesos oficiais FAP/MPS)
A4: A1 Peso Gravidade (w_G) | B4: 0.5 | C4: 0,50 — peso oficial Portaria FAP/MPS
A5: A2 Peso Frequência (w_F) | B5: 0.35 | C5: 0,35 — peso oficial Portaria FAP/MPS
A6: A3 Peso Custo (w_C) | B6: 0.15 | C6: 0,15 — peso oficial Portaria FAP/MPS
A7: A4 Verificação soma (= A1+A2+A3) | B7: =B4+B5+B6 -> 1 | C7: Deve ser 1,00
A8: BLOCO B — PONTO DE REFERÊNCIA
A9: B1 IC de Referência (IC_ref) | B9: 50 | C9: Mediana teórica da escala percentil 0–100
A10: BLOCO C — LIMITES DA RELATIVIDADE
A11: C1 Limite inferior (desagravo máximo) | B11: 0.75 | C11: 0,75 = desagravo de até 25%
A12: C2 Limite superior (agravo máximo) | B12: 1.4 | C12: 1,40 = agravo de até 40%
A13: BLOCO D — LIMIARES DAS CLASSES
A14: D1 Classe Preferencial ≤ | B14: 0.875 | C14: IC < 43,75
A15: D2 Classe Baixo ≤ | B15: 0.95 | C15: IC 43,75–47,50
A16: D3 Classe Médio ≤ | B16: 1.075 | C16: IC 47,50–53,75
A17: D4 Classe Alto ≤ | B17: 1.225 | C17: IC 53,75–61,25
A18: D5 Classe Elevado (> D4) | B18: 1.225 | C18: IC > 61,25
A19: BLOCO E — ESTATÍSTICAS DOS DADOS FAP (referência)
A20: E1 N observações (ICs > 0) | B20: 280 | C20: ICs válidos nos PDFs FAP vigências 2024+2025
A21: E2 IC Médio observado | B21: 54.25 | C21: Média dos ICs calculados — referência analítica
A22: E3 IC Desvio Padrão | B22: 24.2 | C22: Dispersão — usada no teste z
A23: E4 IC Mediana observada | B23: 55.36 | C23: Mediana empírica
A24: E5 IC Mínimo observado | B24: 2.29
A25: E6 IC Máximo observado | B25: 99.89
A26: E7 IC Quartil 1 (Q1) | B26: 36.69
A27: E8 IC Quartil 3 (Q3) | B27: 72.85
A28: BLOCO F — TESTE Z (IC_ref=50 vs média observada)
A29: F1 Estatística z = (E2−B1) / (E3/√E1) | B29: =(B21-B8)/((B22/SQRT(B20))) -> 37.51141 | C29: z>1,96 → rejeitar H0 α=5%
A30: F2 |z| > 1,96? | B30: =IF(ABS(B28)>1.96,"SIM — rejeitar H0","NÃO — não rejeitar H0") -> NÃO — não rejeitar H0
A31: BLOCO G — CONTAGENS GERAIS
A32: G1 Total subclasses CNAE | B32: 1332
A33: G2 Subclasses com FAP calculado | B33: 146
A34: G3 Subclasses com fallback CNAE-STG | B34: 1186 | C34: =G1-G2 -> 0
A35: G4 Divisões com conflito intra-grupo | B35: 21 | C35: Veja aba AUDITORIA

Sheet 02_METODOLOGIA
A1: METODOLOGIA — MOTOR DE CÁLCULO DE RELATIVIDADES POR CNAE | VIDA CAPITAL GLOBAL
A2: Fundamentos, Fórmulas e Análise Crítica | STG Seguros S.A. — 2026
A3: 1. OBJETIVO
A4: Propósito | B4: Calcular, com base nos dados públicos FAP/MPS, agravos e desagravos sobre a taxa pura do produto Vida Capital Global em função da atividade econômica (CNAE) do estipulante.
A5: Fórmula de aplicação | B5: TP_ajustada = TP_base × Relatividade_CNAE
A7: 2. FONTE DOS DADOS
A8: FAP / Ministério da Previdência Social | B8: Percentis de Frequência, Gravidade e Custo por subclasse CNAE 2.3. Publicados anualmente no portal gov.br/previdencia. Cobertura: ~3,4 milhões de estabelecimentos brasileiros.
A9: Vigência 2024 — dados 2021-2022 | B9: Portaria Interministerial MPS/MF nº 1, de 20/09/2023
A10: Vigência 2025 — dados 2022-2023 | B10: Portaria Interministerial MPS/MF nº 4, de 10/09/2024
A12: 3. FÓRMULA DO ÍNDICE COMPOSTO (IC)
A13: IC = w_G × P_Gravidade + w_F × P_Frequência + w_C × P_Custo
A14: Pesos (parâmetros A1–A3 da aba 01_PARÂMETROS) | B14: w_G=0,50 | w_F=0,35 | w_C=0,15 | Soma=1,00 (fórmula oficial FAP)
A15: Escala de IC | B15: 0 a 100. Quanto maior, maior a acidentalidade relativa da subclasse.
A17: 4. PONTO DE REFERÊNCIA IC_ref = 50
A18: Definição | B18: IC_ref=50 é o ponto médio teórico da escala de percentis [0,100] — mediana teórica da distribuição uniforme.
A19: Por que 50 e não a média das subclasses disponíveis? | B19: Os PDFs FAP cobrem ~163 subclasses concentradas em agropecuária e extrativismo — setores acima da média de acidentalidade. Usar a média dessas subclasses como referência criaria viés de seleção: agravos subestimados, desagravos superestimados. IC_ref=50 é transparente, defensável e independente da amostra.
A21: 5. CÁLCULO DA RELATIVIDADE
A22: Relatividade Bruta | B22: Relat_bruta = IC_médio / IC_ref
A23: IC Médio | B23: Média simples dos ICs dos dois anos disponíveis (2023 e 2024)
A24: Relatividade Final | B24: Relat_final = MAX(C1 ; MIN(C2 ; Relat_bruta)) — parâmetros C1=0,75 e C2=1,40 na aba 01_PARÂMETROS
A25: Ajuste sobre a TP | B25: Ajuste_% = (Relat_final − 1,00) × 100
A27: 6. ANÁLISE CRÍTICA — CONFLITOS INTRA-DIVISÃO
A28: O que são conflitos | B28: Subclasses da mesma divisão CNAE com classes de risco opostas (ex: Preferencial e Elevado dentro de 08.10).
A29: Fazem sentido? | B29: MAJORITARIAMENTE SIM. Dentro de uma divisão, diferentes subclasses têm natureza de trabalho radicalmente diferente: • Extração em frente de lavra (alto risco) vs. beneficiamento em galpão (menor risco) • Pesca oceânica (alto) vs. apoio à pesca em escritório (baixo) • Criação intensiva (alto) vs. criação extensiva (baixo)
A30: Casos para revisão | B30: Alguns conflitos podem decorrer de amostras pequenas no FAP (IC instável). A aba 06_AUDITORIA_CONSISTÊNCIA identifica e classifica cada conflito com flag de alerta.
A31: Regra adotada | B31: Cada subclasse mantém sua relatividade calculada individualmente pelo FAP. NÃO se aplica correção automática. Correções manuais devem ser documentadas e aprovadas pelo atuário responsável.
A33: 7. TRATAMENTO SEM DADOS FAP
A34: Fallback | B34: Subclasse sem dados FAP usa o coeficiente CNAE-STG original: Baixo=0,90 | Médio=1,00 | Alto=1,15
A36: 8. RASTREABILIDADE
A37: Todos os números são calculados por fórmula | B37: Nenhum valor foi colado como constante no motor. Todas as células de resultado referenciam a aba 01_PARÂMETROS ou a aba 03_FONTE_FAP.
A38: Cadeia de dependências | B38: 01_PARÂMETROS → 03_FONTE_FAP → 04_MOTOR_CÁLCULO → 05_RESULTADOS
A39: Para auditar um número | B39: Selecione a célula → Ctrl+[ para seguir dependentes | Ctrl+] para ver precedentes
A41: 9. REVISÃO
A42: Periodicidade | B42: Anual — setembro, com publicação dos novos percentis FAP pelo MPS
A43: Responsável | B43: Atuário Responsável Técnico | MIBA 2664 | STG Seguros S.A.

Sheet 03_FONTE_FAP
A1: FONTE DE DADOS — FAP / MPS | Percentis de Frequência, Gravidade e Custo por CNAE
A2: Portarias MPS/MF nº1/2023 (vigência 2024) e nº4/2024 (vigência 2025) | IC = w_G×Grav + w_F×Freq + w_C×Custo
A3: IDENTIFICAÇÃO | C3: ▶ FAP VIGÊNCIA 2024 (dados 2021–2022) | H3: ▶ FAP VIGÊNCIA 2025 (dados 2022–2023) | M3: ▶ RESULTADO
A4: CNAE | B4: Descrição Subclasse | C4: P_Freq | D4: P_Grav | E4: P_Custo | F4: IC 2023 (fórmula) | G4: Válido? | H4: P_Freq | I4: P_Grav | J4: P_Custo | K4: IC 2024 (fórmula) | L4: Válido? | M4: IC Médio (fórmula) | N4: Relat. Bruta (fórmula) | O4: Relat. Final (fórmula)
A5: 01.11-3/01 | B5: Cultivo de arroz | C5: 40.66 | D5: 59.8 | E5: 72.16 | F5: ='01_PARÂMETROS'!$B$4*D5+'01_PARÂMETROS'!$B$5*C5+'01_PARÂMETROS'!$B$6*E5 -> 54.955 | G5: =IF(AND(C5=0,D5=0,E5=0),"✗","✓") -> ✓ | H5: 46.19 | I5: 68.81 | J5: 44.91 | K5: ='01_PARÂMETROS'!$B$4*I5+'01_PARÂMETROS'!$B$5*H5+'01_PARÂMETROS'!$B$6*J5 -> 57.308 | L5: =IF(AND(H5=0,I5=0,J5=0),"✗","✓") -> ✓ | M5: =AVERAGE(F5,K5) -> 56.1315 | N5: =IFERROR(M5/'01_PARÂMETROS'!$B$9,"") -> 1.12263 | O5: =IFERROR(MAX('01_PARÂMETROS'!$B$11,MIN('01_PARÂMETROS'!$B$12,N5)),"") -> 1.12263
A6: 01.11-3/02 | B6: Cultivo de milho | C6: 45.93 | D6: 47.52 | E6: 56.06 | F6: ='01_PARÂMETROS'!$B$4*D6+'01_PARÂMETROS'!$B$5*C6+'01_PARÂMETROS'!$B$6*E6 -> 48.2445 | G6: =IF(AND(C6=0,D6=0,E6=0),"✗","✓") -> ✓ | H6: 30.92 | I6: 29.01 | J6: 21.91 | K6: ='01_PARÂMETROS'!$B$4*I6+'01_PARÂMETROS'!$B$5*H6+'01_PARÂMETROS'!$B$6*J6 -> 28.6135 | L6: =IF(AND(H6=0,I6=0,J6=0),"✗","✓") -> ✓ | M6: =AVERAGE(F6,K6) -> 38.429 | N6: =IFERROR(M6/'01_PARÂMETROS'!$B$9,"") -> 0.76858 | O6: =IFERROR(MAX('01_PARÂMETROS'!$B$11,MIN('01_PARÂMETROS'!$B$12,N6)),"") -> 0.76858
A7: 01.11-3/03 | B7: Cultivo de trigo | C7: 36.32 | D7: 23.02 | E7: 13.63 | F7: ='01_PARÂMETROS'!$B$4*D7+'01_PARÂMETROS'!$B$5*C7+'01_PARÂMETROS'!$B$6*E7 -> 26.2665 | G7: =IF(AND(C7=0,D7=0,E7=0),"✗","✓") -> ✓ | H7: 56.35 | I7: 0 | J7: 0 | K7: ='01_PARÂMETROS'!$B$4*I7+'01_PARÂMETROS'!$B$5*H7+'01_PARÂMETROS'!$B$6*J7 -> 19.7225 | L7: =IF(AND(H7=0,I7=0,J7=0),"✗","✓") -> ✓ | M7: =AVERAGE(F7,K7) -> 22.9945 | N7: =IFERROR(M7/'01_PARÂMETROS'!$B$9,"") -> 0.45989 | O7: =IFERROR(MAX('01_PARÂMETROS'!$B$11,MIN('01_PARÂMETROS'!$B$12,N7)),"") -> 0.75
A8: 01.11-3/99 | B8: Cultivo de outros cereais não especificados anteriormente | C8: 42.75 | D8: 50.21 | E8: 48.21 | F8: ='01_PARÂMETROS'!$B$4*D8+'01_PARÂMETROS'!$B$5*C8+'01_PARÂMETROS'!$B$6*E8 -> 47.299 | G8: =IF(AND(C8=0,D8=0,E8=0),"✗","✓") -> ✓ | H8: 62.39 | I8: 73.86 | J8: 69.02 | K8: ='01_PARÂMETROS'!$B$4*I8+'01_PARÂMETROS'!$B$5*H8+'01_PARÂMETROS'!$B$6*J8 -> 69.1195 | L8: =IF(AND(H8=0,I8=0,J8=0),"✗","✓") -> ✓ | M8: =AVERAGE(F8,K8) -> 58.20925 | N8: =IFERROR(M8/'01_PARÂMETROS'!$B$9,"") -> 1.164185 | O8: =IFERROR(MAX('01_PARÂMETROS'!$B$11,MIN('01_PARÂMETROS'!$B$12,N8)),"") -> 1.164185
A9: 01.12-1/01 | B9: Cultivo de algodão herbáceo | C9: 76.96 | D9: 54.81 | E9: 60.18 | F9: ='01_PARÂMETROS'!$B$4*D9+'01_PARÂMETROS'!$B$5*C9+'01_PARÂMETROS'!$B$6*E9 -> 63.368 | G9: =IF(AND(C9=0,D9=0,E9=0),"✗","✓") -> ✓ | H9: 58.36 | I9: 36.19 | J9: 52.58 | K9: ='01_PARÂMETROS'!$B$4*I9+'01_PARÂMETROS'!$B$5*H9+'01_PARÂMETROS'!$B$6*J9 -> 46.408 | L9: =IF(AND(H9=0,I9=0,J9=0),"✗","✓") -> ✓ | M9: =AVERAGE(F9,K9) -> 54.888 | N9: =IFERROR(M9/'01_PARÂMETROS'!$B$9,"") -> 1.09776 | O9: =IFERROR(MAX('01_PARÂMETROS'!$B$11,MIN('01_PARÂMETROS'!$B$12,N9)),"") -> 1.09776
A10: 01.12-1/02 | B10: Cultivo de juta | C10: 13.2 | D10: 56.71 | E10: 25.68 | F10: ='01_PARÂMETROS'!$B$4*D10+'01_PARÂMETROS'!$B$5*C10+'01_PARÂMETROS'!$B$6*E10 -> 36.827 | G10: =IF(AND(C10=0,D10=0,E10=0),"✗","✓") -> ✓ | H10: 0 | I10: 0 | J10: 0 | K10: 0 | L10: =IF(AND(H10=0,I10=0,J10=0),"✗","✓") -> ✗ | M10: =F10 -> 36.827 | N10: =IFERROR(M10/'01_PARÂMETROS'!$B$9,"") -> 0.73654 | O10: =IFERROR(MAX('01_PARÂMETROS'!$B$11,MIN('01_PARÂMETROS'!$B$12,N10)),"") -> 0.75
A11: 01.12-1/99 | B11: Cultivo de outras fibras de lavoura temporária não especificadas anteriormente | C11: 0 | D11: 0 | E11: 0 | F11: 0 | G11: =IF(AND(C11=0,D11=0,E11=0),"✗","✓") -> ✗ | H11: 0 | I11: 0 | J11: 0 | K11: 0 | L11: =IF(AND(H11=0,I11=0,J11=0),"✗","✓") -> ✗
A12: 01.13-0/00 | B12: Cultivo de cana-de-açúcar | C12: 69.82 | D12: 72.49 | E12: 69.86 | F12: ='01_PARÂMETROS'!$B$4*D12+'01_PARÂMETROS'!$B$5*C12+'01_PARÂMETROS'!$B$6*E12 -> 71.161 | G12: =IF(AND(C12=0,D12=0,E12=0),"✗","✓") -> ✓ | H12: 70.46 | I12: 69.6 | J12: 65.46 | K12: ='01_PARÂMETROS'!$B$4*I12+'01_PARÂMETROS'!$B$5*H12+'01_PARÂMETROS'!$B$6*J12 -> 69.28 | L12: =IF(AND(H12=0,I12=0,J12=0),"✗","✓") -> ✓ | M12: =AVERAGE(F12,K12) -> 70.2205 | N12: =IFERROR(M12/'01_PARÂMETROS'!$B$9,"") -> 1.40441 | O12: =IFERROR(MAX('01_PARÂMETROS'!$B$11,MIN('01_PARÂMETROS'!$B$12,N12)),"") -> 1.4
A13: 01.14-8/00 | B13: Cultivo de fumo | C13: 70.44 | D13: 53.7 | E13: 22.59 | F13: ='01_PARÂMETROS'!$B$4*D13+'01_PARÂMETROS'!$B$5*C13+'01_PARÂMETROS'!$B$6*E13 -> 54.8925 | G13: =IF(AND(C13=0,D13=0,E13=0),"✗","✓") -> ✓ | H13: 76.12 | I13: 52.78 | J13: 43.96 | K13: ='01_PARÂMETROS'!$B$4*I13+'01_PARÂMETROS'!$B$5*H13+'01_PARÂMETROS'!$B$6*J13 -> 59.626 | L13: =IF(AND(H13=0,I13=0,J13=0),"✗","✓") -> ✓ | M13: =AVERAGE(F13,K13) -> 57.25925 | N13: =IFERROR(M13/'01_PARÂMETROS'!$B$9,"") -> 1.145185 | O13: =IFERROR(MAX('01_PARÂMETROS'!$B$11,MIN('01_PARÂMETROS'!$B$12,N13)),"") -> 1.145185
A14: 01.15-6/00 | B14: Cultivo de soja | C14: 77.89 | D14: 48.71 | E14: 39.88 | F14: ='01_PARÂMETROS'!$B$4*D14+'01_PARÂMETROS'!$B$5*C14+'01_PARÂMETROS'!$B$6*E14 -> 57.5985 | G14: =IF(AND(C14=0,D14=0,E14=0),"✗","✓") -> ✓ | H14: 77.9 | I14: 52.22 | J14: 39.14 | K14: ='01_PARÂMETROS'!$B$4*I14+'01_PARÂMETROS'!$B$5*H14+'01_PARÂMETROS'!$B$6*J14 -> 59.246 | L14: =IF(AND(H14=0,I14=0,J14=0),"✗","✓") -> ✓ | M14: =AVERAGE(F14,K14) -> 58.42225 | N14: =IFERROR(M14/'01_PARÂMETROS'!$B$9,"") -> 1.168445 | O14: =IFERROR(MAX('01_PARÂMETROS'!$B$11,MIN('01_PARÂMETROS'!$B$12,N14)),"") -> 1.168445
A15: 01.16-4/01 | B15: Cultivo de amendoim | C15: 55.01 | D15: 66.7 | E15: 6.97 | F15: ='01_PARÂMETROS'!$B$4*D15+'01_PARÂMETROS'!$B$5*C15+'01_PARÂMETROS'!$B$6*E15 -> 53.649 | G15: =IF(AND(C15=0,D15=0,E15=0),"✗","✓") -> ✓ | H15: 0 | I15: 0 | J15: 0 | K15: 0 | L15: =IF(AND(H15=0,I15=0,J15=0),"✗","✓") -> ✗ | M15: =F15 -> 53.649 | N15: =IFERROR(M15/'01_PARÂMETROS'!$B$9,"") -> 1.07298 | O15: =IFERROR(MAX('01_PARÂMETROS'!$B$11,MIN('01_PARÂMETROS'!$B$12,N15)),"") -> 1.07298
A16: 01.16-4/02 | B16: Cultivo de girassol | C16: 0 | D16: 0 | E16: 0 | F16: 0 | G16: =IF(AND(C16=0,D16=0,E16=0),"✗","✓") -> ✗ | H16: 0 | I16: 0 | J16: 0 | K16: 0 | L16: =IF(AND(H16=0,I16=0,J16=0),"✗","✓") -> ✗
A17: 01.16-4/03 | B17: Cultivo de mamona | C17: 0 | D17: 0 | E17: 0 | F17: 0 | G17: =IF(AND(C17=0,D17=0,E17=0),"✗","✓") -> ✗ | H17: 0 | I17: 0 | J17: 0 | K17: 0 | L17: =IF(AND(H17=0,I17=0,J17=0),"✗","✓") -> ✗
A18: 01.16-4/99 | B18: Cultivo de outras oleaginosas de lavoura temporária não especificadas anteriormente | C18: 11.5 | D18: 8.36 | E18: 6.65 | F18: ='01_PARÂMETROS'!$B$4*D18+'01_PARÂMETROS'!$B$5*C18+'01_PARÂMETROS'!$B$6*E18 -> 9.2025 | G18: =IF(AND(C18=0,D18=0,E18=0),"✗","✓") -> ✓ | H18: 8.2 | I18: 33.75 | J18: 68.62 | K18: ='01_PARÂMETROS'!$B$4*I18+'01_PARÂMETROS'!$B$5*H18+'01_PARÂMETROS'!$B$6*J18 -> 30.038 | L18: =IF(AND(H18=0,I18=0,J18=0),"✗","✓") -> ✓ | M18: =AVERAGE(F18,K18) -> 19.62025 | N18: =IFERROR(M18/'01_PARÂMETROS'!$B$9,"") -> 0.392405 | O18: =IFERROR(MAX('01_PARÂMETROS'!$B$11,MIN('01_PARÂMETROS'!$B$12,N18)),"") -> 0.75
A19: 01.19-9/01 | B19: Cultivo de abacaxi | C19: 0 | D19: 0 | E19: 0 | F19: 0 | G19: =IF(AND(C19=0,D19=0,E19=0),"✗","✓") -> ✗ | H19: 0 | I19: 0 | J19: 0 | K19: 0 | L19: =IF(AND(H19=0,I19=0,J19=0),"✗","✓") -> ✗
A20: 01.19-9/02 | B20: Cultivo de alho | C20: 18.55 | D20: 22.7 | E20: 9.11 | F20: ='01_PARÂMETROS'!$B$4*D20+'01_PARÂMETROS'!$B$5*C20+'01_PARÂMETROS'!$B$6*E20 -> 19.209 | G20: =IF(AND(C20=0,D20=0,E20=0),"✗","✓") -> ✓ | H20: 22.7 | I20: 21.9 | J20: 6.66 | K20: ='01_PARÂMETROS'!$B$4*I20+'01_PARÂMETROS'!$B$5*H20+'01_PARÂMETROS'!$B$6*J20 -> 19.894 | L20: =IF(AND(H20=0,I20=0,J20=0),"✗","✓") -> ✓ | M20: =AVERAGE(F20,K20) -> 19.5515 | N20: =IFERROR(M20/'01_PARÂMETROS'!$B$9,"") -> 0.39103 | O20: =IFERROR(MAX('01_PARÂMETROS'!$B$11,MIN('01_PARÂMETROS'!$B$12,N20)),"") -> 0.75
A21: 01.19-9/03 | B21: Cultivo de batata-inglesa | C21: 32.52 | D21: 62.02 | E21: 70.02 | F21: ='01_PARÂMETROS'!$B$4*D21+'01_PARÂMETROS'!$B$5*C21+'01_PARÂMETROS'!$B$6*E21 -> 52.895 | G21: =IF(AND(C21=0,D21=0,E21=0),"✗","✓") -> ✓ | H21: 54.1 | I21: 70.07 | J21: 58.43 | K21: ='01_PARÂMETROS'!$B$4*I21+'01_PARÂMETROS'!$B$5*H21+'01_PARÂMETROS'!$B$6*J21 -> 62.7345 | L21: =IF(AND(H21=0,I21=0,J21=0),"✗","✓") -> ✓ | M21: =AVERAGE(F21,K21) -> 57.81475 | N21: =IFERROR(M21/'01_PARÂMETROS'!$B$9,"") -> 1.156295 | O21: =IFERROR(MAX('01_PARÂMETROS'!$B$11,MIN('01_PARÂMETROS'!$B$12,N21)),"") -> 1.156295
A22: 01.19-9/04 | B22: Cultivo de cebola | C22: 9.79 | D22: 0 | E22: 0 | F22: ='01_PARÂMETROS'!$B$4*D22+'01_PARÂMETROS'!$B$5*C22+'01_PARÂMETROS'!$B$6*E22 -> 3.4265 | G22: =IF(AND(C22=0,D22=0,E22=0),"✗","✓") -> ✓ | H22: 25.34 | I22: 51.28 | J22: 12.91 | K22: ='01_PARÂMETROS'!$B$4*I22+'01_PARÂMETROS'!$B$5*H22+'01_PARÂMETROS'!$B$6*J22 -> 36.4455 | L22: =IF(AND(H22=0,I22=0,J22=0),"✗","✓") -> ✓ | M22: =AVERAGE(F22,K22) -> 19.936 | N22: =IFERROR(M22/'01_PARÂMETROS'!$B$9,"") -> 0.39872 | O22: =IFERROR(MAX('01_PARÂMETROS'!$B$11,MIN('01_PARÂMETROS'!$B$12,N22)),"") -> 0.75
A23: 01.19-9/05 | B23: Cultivo de feijão | C23: 46.4 | D23: 33.72 | E23: 90.24 | F23: ='01_PARÂMETROS'!$B$4*D23+'01_PARÂMETROS'!$B$5*C23+'01_PARÂMETROS'!$B$6*E23 -> 46.636 | G23: =IF(AND(C23=0,D23=0,E23=0),"✗","✓") -> ✓ | H23: 46.27 | I23: 33.27 | J23: 86.4 | K23: ='01_PARÂMETROS'!$B$4*I23+'01_PARÂMETROS'!$B$5*H23+'01_PARÂMETROS'!$B$6*J23 -> 45.7895 | L23: =IF(AND(H23=0,I23=0,J23=0),"✗","✓") -> ✓ | M23: =AVERAGE(F23,K23) -> 46.21275 | N23: =IFERROR(M23/'01_PARÂMETROS'!$B$9,"") -> 0.924255 | O23: =IFERROR(MAX('01_PARÂMETROS'!$B$11,MIN('01_PARÂMETROS'!$B$12,N23)),"") -> 0.924255
A24: 01.19-9/06 | B24: Cultivo de mandioca | C24: 20.11 | D24: 0 | E24: 0 | F24: ='01_PARÂMETROS'!$B$4*D24+'01_PARÂMETROS'!$B$5*C24+'01_PARÂMETROS'!$B$6*E24 -> 7.0385 | G24: =IF(AND(C24=0,D24=0,E24=0),"✗","✓") -> ✓ | H24: 33.01 | I24: 9.27 | J24: 18.28 | K24: ='01_PARÂMETROS'!$B$4*I24+'01_PARÂMETROS'!$B$5*H24+'01_PARÂMETROS'!$B$6*J24 -> 18.9305 | L24: =IF(AND(H24=0,I24=0,J24=0),"✗","✓") -> ✓ | M24: =AVERAGE(F24,K24) -> 12.9845 | N24: =IFERROR(M24/'01_PARÂMETROS'!$B$9,"") -> 0.25969 | O24: =IFERROR(MAX('01_PARÂMETROS'!$B$11,MIN('01_PARÂMETROS'!$B$12,N24)),"") -> 0.75
A25: 01.19-9/07 | B25: Cultivo de melão | C25: 69.59 | D25: 46.8 | E25: 50.98 | F25: ='01_PARÂMETROS'!$B$4*D25+'01_PARÂMETROS'!$B$5*C25+'01_PARÂMETROS'!$B$6*E25 -> 55.4035 | G25: =IF(AND(C25=0,D25=0,E25=0),"✗","✓") -> ✓ | H25: 61.7 | I25: 35.09 | J25: 48.07 | K25: ='01_PARÂMETROS'!$B$4*I25+'01_PARÂMETROS'!$B$5*H25+'01_PARÂMETROS'!$B$6*J25 -> 46.3505 | L25: =IF(AND(H25=0,I25=0,J25=0),"✗","✓") -> ✓ | M25: =AVERAGE(F25,K25) -> 50.877 | N25: =IFERROR(M25/'01_PARÂMETROS'!$B$9,"") -> 1.01754 | O25: =IFERROR(MAX('01_PARÂMETROS'!$B$11,MIN('01_PARÂMETROS'!$B$12,N25)),"") -> 1.01754
A26: 01.19-9/08 | B26: Cultivo de melancia | C26: 0 | D26: 0 | E26: 0 | F26: 0 | G26: =IF(AND(C26=0,D26=0,E26=0),"✗","✓") -> ✗ | H26: 0 | I26: 0 | J26: 0 | K26: 0 | L26: =IF(AND(H26=0,I26=0,J26=0),"✗","✓") -> ✗
A27: 01.19-9/09 | B27: Cultivo de tomate rasteiro | C27: 13.82 | D27: 12.08 | E27: 8.4 | F27: ='01_PARÂMETROS'!$B$4*D27+'01_PARÂMETROS'!$B$5*C27+'01_PARÂMETROS'!$B$6*E27 -> 12.137 | G27: =IF(AND(C27=0,D27=0,E27=0),"✗","✓") -> ✓ | H27: 12 | I27: 12.03 | J27: 7.22 | K27: ='01_PARÂMETROS'!$B$4*I27+'01_PARÂMETROS'!$B$5*H27+'01_PARÂMETROS'!$B$6*J27 -> 11.298 | L27: =IF(AND(H27=0,I27=0,J27=0),"✗","✓") -> ✓ | M27: =AVERAGE(F27,K27) -> 11.7175 | N27: =IFERROR(M27/'01_PARÂMETROS'!$B$9,"") -> 0.23435 | O27: =IFERROR(MAX('01_PARÂMETROS'!$B$11,MIN('01_PARÂMETROS'!$B$12,N27)),"") -> 0.75
A28: 01.19-9/99 | B28: Cultivo de outras plantas de lavoura temporária não especificadas anteriormente | C28: 76.49 | D28: 65.51 | E28: 67.24 | F28: ='01_PARÂMETROS'!$B$4*D28+'01_PARÂMETROS'!$B$5*C28+'01_PARÂMETROS'!$B$6*E28 -> 69.6125 | G28: =IF(AND(C28=0,D28=0,E28=0),"✗","✓") -> ✓ | H28: 79.99 | I28: 48.59 | J28: 45.31 | K28: ='01_PARÂMETROS'!$B$4*I28+'01_PARÂMETROS'!$B$5*H28+'01_PARÂMETROS'!$B$6*J28 -> 59.088 | L28: =IF(AND(H28=0,I28=0,J28=0),"✗","✓") -> ✓ | M28: =AVERAGE(F28,K28) -> 64.35025 | N28: =IFERROR(M28/'01_PARÂMETROS'!$B$9,"") -> 1.287005 | O28: =IFERROR(MAX('01_PARÂMETROS'!$B$11,MIN('01_PARÂMETROS'!$B$12,N28)),"") -> 1.287005
A29: 01.21-1/01 | B29: Horticultura, exceto morango | C29: 34.69 | D29: 29.28 | E29: 34.65 | F29: ='01_PARÂMETROS'!$B$4*D29+'01_PARÂMETROS'!$B$5*C29+'01_PARÂMETROS'!$B$6*E29 -> 31.979 | G29: =IF(AND(C29=0,D29=0,E29=0),"✗","✓") -> ✓ | H29: 40.3 | I29: 32.09 | J29: 32.9 | K29: ='01_PARÂMETROS'!$B$4*I29+'01_PARÂMETROS'!$B$5*H29+'01_PARÂMETROS'!$B$6*J29 -> 35.085 | L29: =IF(AND(H29=0,I29=0,J29=0),"✗","✓") -> ✓ | M29: =AVERAGE(F29,K29) -> 33.532 | N29: =IFERROR(M29/'01_PARÂMETROS'!$B$9,"") -> 0.67064 | O29: =IFERROR(MAX('01_PARÂMETROS'!$B$11,MIN('01_PARÂMETROS'!$B$12,N29)),"") -> 0.75
A30: 01.21-1/02 | B30: Cultivo de morango | C30: 39.96 | D30: 9.94 | E30: 6.73 | F30: ='01_PARÂMETROS'!$B$4*D30+'01_PARÂMETROS'!$B$5*C30+'01_PARÂMETROS'!$B$6*E30 -> 19.9655 | G30: =IF(AND(C30=0,D30=0,E30=0),"✗","✓") -> ✓ | H30: 62.94 | I30: 71.88 | J30: 84.27 | K30: ='01_PARÂMETROS'!$B$4*I30+'01_PARÂMETROS'!$B$5*H30+'01_PARÂMETROS'!$B$6*J30 -> 70.6095 | L30: =IF(AND(H30=0,I30=0,J30=0),"✗","✓") -> ✓ | M30: =AVERAGE(F30,K30) -> 45.2875 | N30: =IFERROR(M30/'01_PARÂMETROS'!$B$9,"") -> 0.90575 | O30: =IFERROR(MAX('01_PARÂMETROS'!$B$11,MIN('01_PARÂMETROS'!$B$12,N30)),"") -> 0.90575
A31: 01.22-9/00 | B31: Cultivo de flores e plantas ornamentais | C31: 23.36 | D31: 37.85 | E31: 56.69 | F31: ='01_PARÂMETROS'!$B$4*D31+'01_PARÂMETROS'!$B$5*C31+'01_PARÂMETROS'!$B$6*E31 -> 35.6045 | G31: =IF(AND(C31=0,D31=0,E31=0),"✗","✓") -> ✓ | H31: 27.43 | I31: 33.67 | J31: 73.13 | K31: ='01_PARÂMETROS'!$B$4*I31+'01_PARÂMETROS'!$B$5*H31+'01_PARÂMETROS'!$B$6*J31 -> 37.405 | L31: =IF(AND(H31=0,I31=0,J31=0),"✗","✓") -> ✓ | M31: =AVERAGE(F31,K31) -> 36.50475 | N31: =IFERROR(M31/'01_PARÂMETROS'!$B$9,"") -> 0.730095 | O31: =IFERROR(MAX('01_PARÂMETROS'!$B$11,MIN('01_PARÂMETROS'!$B$12,N31)),"") -> 0.75
A32: 01.31-8/00 | B32: Cultivo de laranja | C32: 71.14 | D32: 72.8 | E32: 70.18 | F32: ='01_PARÂMETROS'!$B$4*D32+'01_PARÂMETROS'!$B$5*C32+'01_PARÂMETROS'!$B$6*E32 -> 71.826 | G32: =IF(AND(C32=0,D32=0,E32=0),"✗","✓") -> ✓ | H32: 80.77 | I32: 74.17 | J32: 67.83 | K32: ='01_PARÂMETROS'!$B$4*I32+'01_PARÂMETROS'!$B$5*H32+'01_PARÂMETROS'!$B$6*J32 -> 75.529 | L32: =IF(AND(H32=0,I32=0,J32=0),"✗","✓") -> ✓ | M32: =AVERAGE(F32,K32) -> 73.6775 | N32: =IFERROR(M32/'01_PARÂMETROS'!$B$9,"") -> 1.47355 | O32: =IFERROR(MAX('01_PARÂMETROS'!$B$11,MIN('01_PARÂMETROS'!$B$12,N32)),"") -> 1.4
A33: 01.32-6/00 | B33: Cultivo de uva | C33: 70.13 | D33: 52.11 | E33: 40.91 | F33: ='01_PARÂMETROS'!$B$4*D33+'01_PARÂMETROS'!$B$5*C33+'01_PARÂMETROS'!$B$6*E33 -> 56.737 | G33: =IF(AND(C33=0,D33=0,E33=0),"✗","✓") -> ✓ | H33: 76.97 | I33: 49.14 | J33: 42.62 | K33: ='01_PARÂMETROS'!$B$4*I33+'01_PARÂMETROS'!$B$5*H33+'01_PARÂMETROS'!$B$6*J33 -> 57.9025 | L33: =IF(AND(H33=0,I33=0,J33=0),"✗","✓") -> ✓ | M33: =AVERAGE(F33,K33) -> 57.31975 | N33: =IFERROR(M33/'01_PARÂMETROS'!$B$9,"") -> 1.146395 | O33: =IFERROR(MAX('01_PARÂMETROS'!$B$11,MIN('01_PARÂMETROS'!$B$12,N33)),"") -> 1.146395
A34: 01.33-4/01 | B34: Cultivo de açaí | C34: 18.94 | D34: 38.88 | E34: 5.14 | F34: ='01_PARÂMETROS'!$B$4*D34+'01_PARÂMETROS'!$B$5*C34+'01_PARÂMETROS'!$B$6*E34 -> 26.84 | G34: =IF(AND(C34=0,D34=0,E34=0),"✗","✓") -> ✓ | H34: 39.83 | I34: 60.67 | J34: 11.96 | K34: ='01_PARÂMETROS'!$B$4*I34+'01_PARÂMETROS'!$B$5*H34+'01_PARÂMETROS'!$B$6*J34 -> 46.0695 | L34: =IF(AND(H34=0,I34=0,J34=0),"✗","✓") -> ✓ | M34: =AVERAGE(F34,K34) -> 36.45475 | N34: =IFERROR(M34/'01_PARÂMETROS'!$B$9,"") -> 0.729095 | O34: =IFERROR(MAX('01_PARÂMETROS'!$B$11,MIN('01_PARÂMETROS'!$B$12,N34)),"") -> 0.75
A35: 01.33-4/02 | B35: Cultivo de banana | C35: 72.69 | D35: 63.05 | E35: 38.22 | F35: ='01_PARÂMETROS'!$B$4*D35+'01_PARÂMETROS'!$B$5*C35+'01_PARÂMETROS'!$B$6*E35 -> 62.6995 | G35: =IF(AND(C35=0,D35=0,E35=0),"✗","✓") -> ✓ | H35: 74.33 | I35: 65.49 | J35: 29.03 | K35: ='01_PARÂMETROS'!$B$4*I35+'01_PARÂMETROS'!$B$5*H35+'01_PARÂMETROS'!$B$6*J35 -> 63.115 | L35: =IF(AND(H35=0,I35=0,J35=0),"✗","✓") -> ✓ | M35: =AVERAGE(F35,K35) -> 62.90725 | N35: =IFERROR(M35/'01_PARÂMETROS'!$B$9,"") -> 1.258145 | O35: =IFERROR(MAX('01_PARÂMETROS'!$B$11,MIN('01_PARÂMETROS'!$B$12,N35)),"") -> 1.258145
A36: 01.33-4/03 | B36: Cultivo de caju | C36: 73.78 | D36: 98.89 | E36: 99.6 | F36: ='01_PARÂMETROS'!$B$4*D36+'01_PARÂMETROS'!$B$5*C36+'01_PARÂMETROS'!$B$6*E36 -> 90.208 | G36: =IF(AND(C36=0,D36=0,E36=0),"✗","✓") -> ✓ | H36: 69.22 | I36: 90.12 | J36: 99.36 | K36: ='01_PARÂMETROS'!$B$4*I36+'01_PARÂMETROS'!$B$5*H36+'01_PARÂMETROS'!$B$6*J36 -> 84.191 | L36: =IF(AND(H36=0,I36=0,J36=0),"✗","✓") -> ✓ | M36: =AVERAGE(F36,K36) -> 87.1995 | N36: =IFERROR(M36/'01_PARÂMETROS'!$B$9,"") -> 1.74399 | O36: =IFERROR(MAX('01_PARÂMETROS'!$B$11,MIN('01_PARÂMETROS'!$B$12,N36)),"") -> 1.4
A37: 01.33-4/04 | B37: Cultivo de cítricos, exceto laranja | C37: 39.88 | D37: 41.97 | E37: 14.82 | F37: ='01_PARÂMETROS'!$B$4*D37+'01_PARÂMETROS'!$B$5*C37+'01_PARÂMETROS'!$B$6*E37 -> 37.166 | G37: =IF(AND(C37=0,D37=0,E37=0),"✗","✓") -> ✓ | H37: 45.41 | I37: 44.17 | J37: 15.04 | K37: ='01_PARÂMETROS'!$B$4*I37+'01_PARÂMETROS'!$B$5*H37+'01_PARÂMETROS'!$B$6*J37 -> 40.2345 | L37: =IF(AND(H37=0,I37=0,J37=0),"✗","✓") -> ✓ | M37: =AVERAGE(F37,K37) -> 38.70025 | N37: =IFERROR(M37/'01_PARÂMETROS'!$B$9,"") -> 0.774005 | O37: =IFERROR(MAX('01_PARÂMETROS'!$B$11,MIN('01_PARÂMETROS'!$B$12,N37)),"") -> 0.774005
A38: 01.33-4/05 | B38: Cultivo de coco-da-baía | C38: 86.96 | D38: 49.18 | E38: 54.08 | F38: ='01_PARÂMETROS'!$B$4*D38+'01_PARÂMETROS'!$B$5*C38+'01_PARÂMETROS'!$B$6*E38 -> 63.138 | G38: =IF(AND(C38=0,D38=0,E38=0),"✗","✓") -> ✓ | H38: 88.06 | I38: 58.7 | J38: 52.74 | K38: ='01_PARÂMETROS'!$B$4*I38+'01_PARÂMETROS'!$B$5*H38+'01_PARÂMETROS'!$B$6*J38 -> 68.082 | L38: =IF(AND(H38=0,I38=0,J38=0),"✗","✓") -> ✓ | M38: =AVERAGE(F38,K38) -> 65.61 | N38: =IFERROR(M38/'01_PARÂMETROS'!$B$9,"") -> 1.3122 | O38: =IFERROR(MAX('01_PARÂMETROS'!$B$11,MIN('01_PARÂMETROS'!$B$12,N38)),"") -> 1.3122
A39: 01.33-4/06 | B39: Cultivo de guaraná | C39: 0 | D39: 0 | E39: 0 | F39: 0 | G39: =IF(AND(C39=0,D39=0,E39=0),"✗","✓") -> ✗ | H39: 0 | I39: 0 | J39: 0 | K39: 0 | L39: =IF(AND(H39=0,I39=0,J39=0),"✗","✓") -> ✗
A40: 01.33-4/07 | B40: Cultivo de maçã | C40: 71.61 | D40: 82.56 | E40: 86.2 | F40: ='01_PARÂMETROS'!$B$4*D40+'01_PARÂMETROS'!$B$5*C40+'01_PARÂMETROS'!$B$6*E40 -> 79.2735 | G40: =IF(AND(C40=0,D40=0,E40=0),"✗","✓") -> ✓ | H40: 49.76 | I40: 52.7 | J40: 77.08 | K40: ='01_PARÂMETROS'!$B$4*I40+'01_PARÂMETROS'!$B$5*H40+'01_PARÂMETROS'!$B$6*J40 -> 55.328 | L40: =IF(AND(H40=0,I40=0,J40=0),"✗","✓") -> ✓ | M40: =AVERAGE(F40,K40) -> 67.30075 | N40: =IFERROR(M40/'01_PARÂMETROS'!$B$9,"") -> 1.346015 | O40: =IFERROR(MAX('01_PARÂMETROS'!$B$11,MIN('01_PARÂMETROS'!$B$12,N40)),"") -> 1.346015
...

Sheet 04_MOTOR_CÁLCULO
A1: MOTOR DE CÁLCULO — RELATIVIDADES CNAE | VIDA CAPITAL GLOBAL | STG SEGUROS
A2: Todos os valores são calculados por fórmula — sem constantes coladas. Parâmetros em 01_PARÂMETROS.
A3: IDENTIFICAÇÃO | F3: FAP — ÍNDICES COMPOSTOS | J3: RELATIVIDADE | M3: RESULTADO FINAL
A4: Cód.CNAE | B4: Sec. | C4: Descrição Subclasse | D4: Div. | E4: Class. CNAE | F4: IC 2023 | G4: IC 2024 | H4: IC Médio | I4: IC_ref (param.) | J4: Relat. Bruta | K4: Relat. Final | L4: Ajuste % | M4: Classe | N4: Fonte | O4: Flag Conflito
A5: 0111-3/01 | B5: A | C5: Cultivo de arroz | D5: AGRICULTURA, PEC | E5: Médio | F5: ='03_FONTE_FAP'!F5 -> 54.955 | G5: ='03_FONTE_FAP'!K5 -> 57.308 | H5: ='03_FONTE_FAP'!M5 -> 56.1315 | I5: ='01_PARÂMETROS'!$B$9 -> 50 | J5: =IFERROR(IF(H5=0,1,H5/I5),1) -> 1.12263 | K5: =MAX('01_PARÂMETROS'!$B$11,MIN('01_PARÂMETROS'!$B$12,J5)) -> 1.12263 | L5: =(K5-1) -> 0.12263 | M5: =IF(K5<='01_PARÂMETROS'!$B$14,"Preferencial",IF(K5<='01_PARÂMETROS'!$B$15,"Baixo",IF(K5<='01_PARÂMETROS'!$B$16,"Médio",IF(K5<='01_PARÂMETROS'!$B$17,"Alto","Elevado")))) -> Alto | N5: FAP/MPS | O5: Revisar
A6: 0111-3/02 | B6: A | C6: Cultivo de milho | D6: AGRICULTURA, PEC | E6: Médio | F6: ='03_FONTE_FAP'!F6 -> 48.2445 | G6: ='03_FONTE_FAP'!K6 -> 28.6135 | H6: ='03_FONTE_FAP'!M6 -> 38.429 | I6: ='01_PARÂMETROS'!$B$9 -> 50 | J6: =IFERROR(IF(H6=0,1,H6/I6),1) -> 0.76858 | K6: =MAX('01_PARÂMETROS'!$B$11,MIN('01_PARÂMETROS'!$B$12,J6)) -> 0.76858 | L6: =(K6-1) -> -0.23142 | M6: =IF(K6<='01_PARÂMETROS'!$B$14,"Preferencial",IF(K6<='01_PARÂMETROS'!$B$15,"Baixo",IF(K6<='01_PARÂMETROS'!$B$16,"Médio",IF(K6<='01_PARÂMETROS'!$B$17,"Alto","Elevado")))) -> Preferencial | N6: FAP/MPS | O6: Revisar
A7: 0111-3/03 | B7: A | C7: Cultivo de trigo | D7: AGRICULTURA, PEC | E7: Médio | F7: ='03_FONTE_FAP'!F7 -> 26.2665 | G7: ='03_FONTE_FAP'!K7 -> 19.7225 | H7: ='03_FONTE_FAP'!M7 -> 22.9945 | I7: ='01_PARÂMETROS'!$B$9 -> 50 | J7: =IFERROR(IF(H7=0,1,H7/I7),1) -> 0.45989 | K7: =MAX('01_PARÂMETROS'!$B$11,MIN('01_PARÂMETROS'!$B$12,J7)) -> 0.75 | L7: =(K7-1) -> -0.25 | M7: =IF(K7<='01_PARÂMETROS'!$B$14,"Preferencial",IF(K7<='01_PARÂMETROS'!$B$15,"Baixo",IF(K7<='01_PARÂMETROS'!$B$16,"Médio",IF(K7<='01_PARÂMETROS'!$B$17,"Alto","Elevado")))) -> Preferencial | N7: FAP/MPS | O7: Revisar
A8: 0111-3/99 | B8: A | C8: Cultivo de outros cereais não especificados anteriormente | D8: AGRICULTURA, PEC | E8: Médio | F8: ='03_FONTE_FAP'!F8 -> 47.299 | G8: ='03_FONTE_FAP'!K8 -> 69.1195 | H8: ='03_FONTE_FAP'!M8 -> 58.20925 | I8: ='01_PARÂMETROS'!$B$9 -> 50 | J8: =IFERROR(IF(H8=0,1,H8/I8),1) -> 1.164185 | K8: =MAX('01_PARÂMETROS'!$B$11,MIN('01_PARÂMETROS'!$B$12,J8)) -> 1.164185 | L8: =(K8-1) -> 0.164185 | M8: =IF(K8<='01_PARÂMETROS'!$B$14,"Preferencial",IF(K8<='01_PARÂMETROS'!$B$15,"Baixo",IF(K8<='01_PARÂMETROS'!$B$16,"Médio",IF(K8<='01_PARÂMETROS'!$B$17,"Alto","Elevado")))) -> Alto | N8: FAP/MPS | O8: Revisar
A9: 0112-1/01 | B9: A | C9: Cultivo de algodão herbáceo | D9: AGRICULTURA, PEC | E9: Médio | F9: ='03_FONTE_FAP'!F9 -> 63.368 | G9: ='03_FONTE_FAP'!K9 -> 46.408 | H9: ='03_FONTE_FAP'!M9 -> 54.888 | I9: ='01_PARÂMETROS'!$B$9 -> 50 | J9: =IFERROR(IF(H9=0,1,H9/I9),1) -> 1.09776 | K9: =MAX('01_PARÂMETROS'!$B$11,MIN('01_PARÂMETROS'!$B$12,J9)) -> 1.09776 | L9: =(K9-1) -> 0.09776 | M9: =IF(K9<='01_PARÂMETROS'!$B$14,"Preferencial",IF(K9<='01_PARÂMETROS'!$B$15,"Baixo",IF(K9<='01_PARÂMETROS'!$B$16,"Médio",IF(K9<='01_PARÂMETROS'!$B$17,"Alto","Elevado")))) -> Alto | N9: FAP/MPS | O9: Revisar
A10: 0112-1/02 | B10: A | C10: Cultivo de juta | D10: AGRICULTURA, PEC | E10: Médio | F10: ='03_FONTE_FAP'!F10 -> 36.827 | G10: ='03_FONTE_FAP'!K10 -> 0 | H10: ='03_FONTE_FAP'!M10 -> 36.827 | I10: ='01_PARÂMETROS'!$B$9 -> 50 | J10: =IFERROR(IF(H10=0,1,H10/I10),1) -> 0.73654 | K10: =MAX('01_PARÂMETROS'!$B$11,MIN('01_PARÂMETROS'!$B$12,J10)) -> 0.75 | L10: =(K10-1) -> -0.25 | M10: =IF(K10<='01_PARÂMETROS'!$B$14,"Preferencial",IF(K10<='01_PARÂMETROS'!$B$15,"Baixo",IF(K10<='01_PARÂMETROS'!$B$16,"Médio",IF(K10<='01_PARÂMETROS'!$B$17,"Alto","Elevado")))) -> Preferencial | N10: FAP/MPS | O10: Revisar
A11: 0112-1/99 | B11: A | C11: Cultivo de outras fibras de lavoura temporária não especificadas anteriormente | D11: AGRICULTURA, PEC | E11: Médio | F11: — | G11: — | H11: — | I11: ='01_PARÂMETROS'!$B$9 -> 50 | J11: =1 -> 1 | K11: =MAX('01_PARÂMETROS'!$B$11,MIN('01_PARÂMETROS'!$B$12,J11)) -> 1 | L11: =(K11-1) -> 0 | M11: =IF(K11<='01_PARÂMETROS'!$B$14,"Preferencial",IF(K11<='01_PARÂMETROS'!$B$15,"Baixo",IF(K11<='01_PARÂMETROS'!$B$16,"Médio",IF(K11<='01_PARÂMETROS'!$B$17,"Alto","Elevado")))) -> Médio | N11: CNAE-STG
A12: 0113-0/00 | B12: A | C12: Cultivo de cana-de-açúcar | D12: AGRICULTURA, PEC | E12: Médio | F12: ='03_FONTE_FAP'!F12 -> 71.161 | G12: ='03_FONTE_FAP'!K12 -> 69.28 | H12: ='03_FONTE_FAP'!M12 -> 70.2205 | I12: ='01_PARÂMETROS'!$B$9 -> 50 | J12: =IFERROR(IF(H12=0,1,H12/I12),1) -> 1.40441 | K12: =MAX('01_PARÂMETROS'!$B$11,MIN('01_PARÂMETROS'!$B$12,J12)) -> 1.4 | L12: =(K12-1) -> 0.4 | M12: =IF(K12<='01_PARÂMETROS'!$B$14,"Preferencial",IF(K12<='01_PARÂMETROS'!$B$15,"Baixo",IF(K12<='01_PARÂMETROS'!$B$16,"Médio",IF(K12<='01_PARÂMETROS'!$B$17,"Alto","Elevado")))) -> Elevado | N12: FAP/MPS
A13: 0114-8/00 | B13: A | C13: Cultivo de fumo | D13: AGRICULTURA, PEC | E13: Médio | F13: ='03_FONTE_FAP'!F13 -> 54.8925 | G13: ='03_FONTE_FAP'!K13 -> 59.626 | H13: ='03_FONTE_FAP'!M13 -> 57.25925 | I13: ='01_PARÂMETROS'!$B$9 -> 50 | J13: =IFERROR(IF(H13=0,1,H13/I13),1) -> 1.145185 | K13: =MAX('01_PARÂMETROS'!$B$11,MIN('01_PARÂMETROS'!$B$12,J13)) -> 1.145185 | L13: =(K13-1) -> 0.145185 | M13: =IF(K13<='01_PARÂMETROS'!$B$14,"Preferencial",IF(K13<='01_PARÂMETROS'!$B$15,"Baixo",IF(K13<='01_PARÂMETROS'!$B$16,"Médio",IF(K13<='01_PARÂMETROS'!$B$17,"Alto","Elevado")))) -> Alto | N13: FAP/MPS
A14: 0115-6/00 | B14: A | C14: Cultivo de soja | D14: AGRICULTURA, PEC | E14: Médio | F14: ='03_FONTE_FAP'!F14 -> 57.5985 | G14: ='03_FONTE_FAP'!K14 -> 59.246 | H14: ='03_FONTE_FAP'!M14 -> 58.42225 | I14: ='01_PARÂMETROS'!$B$9 -> 50 | J14: =IFERROR(IF(H14=0,1,H14/I14),1) -> 1.168445 | K14: =MAX('01_PARÂMETROS'!$B$11,MIN('01_PARÂMETROS'!$B$12,J14)) -> 1.168445 | L14: =(K14-1) -> 0.168445 | M14: =IF(K14<='01_PARÂMETROS'!$B$14,"Preferencial",IF(K14<='01_PARÂMETROS'!$B$15,"Baixo",IF(K14<='01_PARÂMETROS'!$B$16,"Médio",IF(K14<='01_PARÂMETROS'!$B$17,"Alto","Elevado")))) -> Alto | N14: FAP/MPS
A15: 0116-4/01 | B15: A | C15: Cultivo de amendoim | D15: AGRICULTURA, PEC | E15: Médio | F15: ='03_FONTE_FAP'!F15 -> 53.649 | G15: ='03_FONTE_FAP'!K15 -> 0 | H15: ='03_FONTE_FAP'!M15 -> 53.649 | I15: ='01_PARÂMETROS'!$B$9 -> 50 | J15: =IFERROR(IF(H15=0,1,H15/I15),1) -> 1.07298 | K15: =MAX('01_PARÂMETROS'!$B$11,MIN('01_PARÂMETROS'!$B$12,J15)) -> 1.07298 | L15: =(K15-1) -> 0.07298 | M15: =IF(K15<='01_PARÂMETROS'!$B$14,"Preferencial",IF(K15<='01_PARÂMETROS'!$B$15,"Baixo",IF(K15<='01_PARÂMETROS'!$B$16,"Médio",IF(K15<='01_PARÂMETROS'!$B$17,"Alto","Elevado")))) -> Médio | N15: FAP/MPS
A16: 0116-4/02 | B16: A | C16: Cultivo de girassol | D16: AGRICULTURA, PEC | E16: Médio | F16: — | G16: — | H16: — | I16: ='01_PARÂMETROS'!$B$9 -> 50 | J16: =1 -> 1 | K16: =MAX('01_PARÂMETROS'!$B$11,MIN('01_PARÂMETROS'!$B$12,J16)) -> 1 | L16: =(K16-1) -> 0 | M16: =IF(K16<='01_PARÂMETROS'!$B$14,"Preferencial",IF(K16<='01_PARÂMETROS'!$B$15,"Baixo",IF(K16<='01_PARÂMETROS'!$B$16,"Médio",IF(K16<='01_PARÂMETROS'!$B$17,"Alto","Elevado")))) -> Médio | N16: CNAE-STG
A17: 0116-4/03 | B17: A | C17: Cultivo de mamona | D17: AGRICULTURA, PEC | E17: Médio | F17: — | G17: — | H17: — | I17: ='01_PARÂMETROS'!$B$9 -> 50 | J17: =1 -> 1 | K17: =MAX('01_PARÂMETROS'!$B$11,MIN('01_PARÂMETROS'!$B$12,J17)) -> 1 | L17: =(K17-1) -> 0 | M17: =IF(K17<='01_PARÂMETROS'!$B$14,"Preferencial",IF(K17<='01_PARÂMETROS'!$B$15,"Baixo",IF(K17<='01_PARÂMETROS'!$B$16,"Médio",IF(K17<='01_PARÂMETROS'!$B$17,"Alto","Elevado")))) -> Médio | N17: CNAE-STG
A18: 0116-4/99 | B18: A | C18: Cultivo de outras oleaginosas de lavoura temporária não especificadas anteriormente | D18: AGRICULTURA, PEC | E18: Médio | F18: ='03_FONTE_FAP'!F18 -> 9.2025 | G18: ='03_FONTE_FAP'!K18 -> 30.038 | H18: ='03_FONTE_FAP'!M18 -> 19.62025 | I18: ='01_PARÂMETROS'!$B$9 -> 50 | J18: =IFERROR(IF(H18=0,1,H18/I18),1) -> 0.392405 | K18: =MAX('01_PARÂMETROS'!$B$11,MIN('01_PARÂMETROS'!$B$12,J18)) -> 0.75 | L18: =(K18-1) -> -0.25 | M18: =IF(K18<='01_PARÂMETROS'!$B$14,"Preferencial",IF(K18<='01_PARÂMETROS'!$B$15,"Baixo",IF(K18<='01_PARÂMETROS'!$B$16,"Médio",IF(K18<='01_PARÂMETROS'!$B$17,"Alto","Elevado")))) -> Preferencial | N18: FAP/MPS
A19: 0119-9/01 | B19: A | C19: Cultivo de abacaxi | D19: AGRICULTURA, PEC | E19: Médio | F19: — | G19: — | H19: — | I19: ='01_PARÂMETROS'!$B$9 -> 50 | J19: =1 -> 1 | K19: =MAX('01_PARÂMETROS'!$B$11,MIN('01_PARÂMETROS'!$B$12,J19)) -> 1 | L19: =(K19-1) -> 0 | M19: =IF(K19<='01_PARÂMETROS'!$B$14,"Preferencial",IF(K19<='01_PARÂMETROS'!$B$15,"Baixo",IF(K19<='01_PARÂMETROS'!$B$16,"Médio",IF(K19<='01_PARÂMETROS'!$B$17,"Alto","Elevado")))) -> Médio | N19: CNAE-STG
A20: 0119-9/02 | B20: A | C20: Cultivo de alho | D20: AGRICULTURA, PEC | E20: Médio | F20: ='03_FONTE_FAP'!F20 -> 19.209 | G20: ='03_FONTE_FAP'!K20 -> 19.894 | H20: ='03_FONTE_FAP'!M20 -> 19.5515 | I20: ='01_PARÂMETROS'!$B$9 -> 50 | J20: =IFERROR(IF(H20=0,1,H20/I20),1) -> 0.39103 | K20: =MAX('01_PARÂMETROS'!$B$11,MIN('01_PARÂMETROS'!$B$12,J20)) -> 0.75 | L20: =(K20-1) -> -0.25 | M20: =IF(K20<='01_PARÂMETROS'!$B$14,"Preferencial",IF(K20<='01_PARÂMETROS'!$B$15,"Baixo",IF(K20<='01_PARÂMETROS'!$B$16,"Médio",IF(K20<='01_PARÂMETROS'!$B$17,"Alto","Elevado")))) -> Preferencial | N20: FAP/MPS | O20: Revisar
A21: 0119-9/03 | B21: A | C21: Cultivo de batata-inglesa | D21: AGRICULTURA, PEC | E21: Médio | F21: ='03_FONTE_FAP'!F21 -> 52.895 | G21: ='03_FONTE_FAP'!K21 -> 62.7345 | H21: ='03_FONTE_FAP'!M21 -> 57.81475 | I21: ='01_PARÂMETROS'!$B$9 -> 50 | J21: =IFERROR(IF(H21=0,1,H21/I21),1) -> 1.156295 | K21: =MAX('01_PARÂMETROS'!$B$11,MIN('01_PARÂMETROS'!$B$12,J21)) -> 1.156295 | L21: =(K21-1) -> 0.156295 | M21: =IF(K21<='01_PARÂMETROS'!$B$14,"Preferencial",IF(K21<='01_PARÂMETROS'!$B$15,"Baixo",IF(K21<='01_PARÂMETROS'!$B$16,"Médio",IF(K21<='01_PARÂMETROS'!$B$17,"Alto","Elevado")))) -> Alto | N21: FAP/MPS | O21: Revisar
A22: 0119-9/04 | B22: A | C22: Cultivo de cebola | D22: AGRICULTURA, PEC | E22: Médio | F22: ='03_FONTE_FAP'!F22 -> 3.4265 | G22: ='03_FONTE_FAP'!K22 -> 36.4455 | H22: ='03_FONTE_FAP'!M22 -> 19.936 | I22: ='01_PARÂMETROS'!$B$9 -> 50 | J22: =IFERROR(IF(H22=0,1,H22/I22),1) -> 0.39872 | K22: =MAX('01_PARÂMETROS'!$B$11,MIN('01_PARÂMETROS'!$B$12,J22)) -> 0.75 | L22: =(K22-1) -> -0.25 | M22: =IF(K22<='01_PARÂMETROS'!$B$14,"Preferencial",IF(K22<='01_PARÂMETROS'!$B$15,"Baixo",IF(K22<='01_PARÂMETROS'!$B$16,"Médio",IF(K22<='01_PARÂMETROS'!$B$17,"Alto","Elevado")))) -> Preferencial | N22: FAP/MPS | O22: Revisar
A23: 0119-9/05 | B23: A | C23: Cultivo de feijão | D23: AGRICULTURA, PEC | E23: Médio | F23: ='03_FONTE_FAP'!F23 -> 46.636 | G23: ='03_FONTE_FAP'!K23 -> 45.7895 | H23: ='03_FONTE_FAP'!M23 -> 46.21275 | I23: ='01_PARÂMETROS'!$B$9 -> 50 | J23: =IFERROR(IF(H23=0,1,H23/I23),1) -> 0.924255 | K23: =MAX('01_PARÂMETROS'!$B$11,MIN('01_PARÂMETROS'!$B$12,J23)) -> 0.924255 | L23: =(K23-1) -> -0.075745 | M23: =IF(K23<='01_PARÂMETROS'!$B$14,"Preferencial",IF(K23<='01_PARÂMETROS'!$B$15,"Baixo",IF(K23<='01_PARÂMETROS'!$B$16,"Médio",IF(K23<='01_PARÂMETROS'!$B$17,"Alto","Elevado")))) -> Baixo | N23: FAP/MPS | O23: Revisar
A24: 0119-9/06 | B24: A | C24: Cultivo de mandioca | D24: AGRICULTURA, PEC | E24: Médio | F24: ='03_FONTE_FAP'!F24 -> 7.0385 | G24: ='03_FONTE_FAP'!K24 -> 18.9305 | H24: ='03_FONTE_FAP'!M24 -> 12.9845 | I24: ='01_PARÂMETROS'!$B$9 -> 50 | J24: =IFERROR(IF(H24=0,1,H24/I24),1) -> 0.25969 | K24: =MAX('01_PARÂMETROS'!$B$11,MIN('01_PARÂMETROS'!$B$12,J24)) -> 0.75 | L24: =(K24-1) -> -0.25 | M24: =IF(K24<='01_PARÂMETROS'!$B$14,"Preferencial",IF(K24<='01_PARÂMETROS'!$B$15,"Baixo",IF(K24<='01_PARÂMETROS'!$B$16,"Médio",IF(K24<='01_PARÂMETROS'!$B$17,"Alto","Elevado")))) -> Preferencial | N24: FAP/MPS | O24: Revisar
A25: 0119-9/07 | B25: A | C25: Cultivo de melão | D25: AGRICULTURA, PEC | E25: Médio | F25: ='03_FONTE_FAP'!F25 -> 55.4035 | G25: ='03_FONTE_FAP'!K25 -> 46.3505 | H25: ='03_FONTE_FAP'!M25 -> 50.877 | I25: ='01_PARÂMETROS'!$B$9 -> 50 | J25: =IFERROR(IF(H25=0,1,H25/I25),1) -> 1.01754 | K25: =MAX('01_PARÂMETROS'!$B$11,MIN('01_PARÂMETROS'!$B$12,J25)) -> 1.01754 | L25: =(K25-1) -> 0.01754 | M25: =IF(K25<='01_PARÂMETROS'!$B$14,"Preferencial",IF(K25<='01_PARÂMETROS'!$B$15,"Baixo",IF(K25<='01_PARÂMETROS'!$B$16,"Médio",IF(K25<='01_PARÂMETROS'!$B$17,"Alto","Elevado")))) -> Médio | N25: FAP/MPS | O25: Revisar
A26: 0119-9/08 | B26: A | C26: Cultivo de melancia | D26: AGRICULTURA, PEC | E26: Médio | F26: — | G26: — | H26: — | I26: ='01_PARÂMETROS'!$B$9 -> 50 | J26: =1 -> 1 | K26: =MAX('01_PARÂMETROS'!$B$11,MIN('01_PARÂMETROS'!$B$12,J26)) -> 1 | L26: =(K26-1) -> 0 | M26: =IF(K26<='01_PARÂMETROS'!$B$14,"Preferencial",IF(K26<='01_PARÂMETROS'!$B$15,"Baixo",IF(K26<='01_PARÂMETROS'!$B$16,"Médio",IF(K26<='01_PARÂMETROS'!$B$17,"Alto","Elevado")))) -> Médio | N26: CNAE-STG
A27: 0119-9/09 | B27: A | C27: Cultivo de tomate rasteiro | D27: AGRICULTURA, PEC | E27: Médio | F27: ='03_FONTE_FAP'!F27 -> 12.137 | G27: ='03_FONTE_FAP'!K27 -> 11.298 | H27: ='03_FONTE_FAP'!M27 -> 11.7175 | I27: ='01_PARÂMETROS'!$B$9 -> 50 | J27: =IFERROR(IF(H27=0,1,H27/I27),1) -> 0.23435 | K27: =MAX('01_PARÂMETROS'!$B$11,MIN('01_PARÂMETROS'!$B$12,J27)) -> 0.75 | L27: =(K27-1) -> -0.25 | M27: =IF(K27<='01_PARÂMETROS'!$B$14,"Preferencial",IF(K27<='01_PARÂMETROS'!$B$15,"Baixo",IF(K27<='01_PARÂMETROS'!$B$16,"Médio",IF(K27<='01_PARÂMETROS'!$B$17,"Alto","Elevado")))) -> Preferencial | N27: FAP/MPS | O27: Revisar
A28: 0119-9/99 | B28: A | C28: Cultivo de outras plantas de lavoura temporária não especificadas anteriormente | D28: AGRICULTURA, PEC | E28: Médio | F28: ='03_FONTE_FAP'!F28 -> 69.6125 | G28: ='03_FONTE_FAP'!K28 -> 59.088 | H28: ='03_FONTE_FAP'!M28 -> 64.35025 | I28: ='01_PARÂMETROS'!$B$9 -> 50 | J28: =IFERROR(IF(H28=0,1,H28/I28),1) -> 1.287005 | K28: =MAX('01_PARÂMETROS'!$B$11,MIN('01_PARÂMETROS'!$B$12,J28)) -> 1.287005 | L28: =(K28-1) -> 0.287005 | M28: =IF(K28<='01_PARÂMETROS'!$B$14,"Preferencial",IF(K28<='01_PARÂMETROS'!$B$15,"Baixo",IF(K28<='01_PARÂMETROS'!$B$16,"Médio",IF(K28<='01_PARÂMETROS'!$B$17,"Alto","Elevado")))) -> Elevado | N28: FAP/MPS | O28: Revisar
A29: 0121-1/01 | B29: A | C29: Horticultura, exceto morango | D29: AGRICULTURA, PEC | E29: Médio | F29: ='03_FONTE_FAP'!F29 -> 31.979 | G29: ='03_FONTE_FAP'!K29 -> 35.085 | H29: ='03_FONTE_FAP'!M29 -> 33.532 | I29: ='01_PARÂMETROS'!$B$9 -> 50 | J29: =IFERROR(IF(H29=0,1,H29/I29),1) -> 0.67064 | K29: =MAX('01_PARÂMETROS'!$B$11,MIN('01_PARÂMETROS'!$B$12,J29)) -> 0.75 | L29: =(K29-1) -> -0.25 | M29: =IF(K29<='01_PARÂMETROS'!$B$14,"Preferencial",IF(K29<='01_PARÂMETROS'!$B$15,"Baixo",IF(K29<='01_PARÂMETROS'!$B$16,"Médio",IF(K29<='01_PARÂMETROS'!$B$17,"Alto","Elevado")))) -> Preferencial | N29: FAP/MPS
A30: 0121-1/02 | B30: A | C30: Cultivo de morango | D30: AGRICULTURA, PEC | E30: Médio | F30: ='03_FONTE_FAP'!F30 -> 19.9655 | G30: ='03_FONTE_FAP'!K30 -> 70.6095 | H30: ='03_FONTE_FAP'!M30 -> 45.2875 | I30: ='01_PARÂMETROS'!$B$9 -> 50 | J30: =IFERROR(IF(H30=0,1,H30/I30),1) -> 0.90575 | K30: =MAX('01_PARÂMETROS'!$B$11,MIN('01_PARÂMETROS'!$B$12,J30)) -> 0.90575 | L30: =(K30-1) -> -0.09425 | M30: =IF(K30<='01_PARÂMETROS'!$B$14,"Preferencial",IF(K30<='01_PARÂMETROS'!$B$15,"Baixo",IF(K30<='01_PARÂMETROS'!$B$16,"Médio",IF(K30<='01_PARÂMETROS'!$B$17,"Alto","Elevado")))) -> Baixo | N30: FAP/MPS
A31: 0122-9/00 | B31: A | C31: Cultivo de flores e plantas ornamentais | D31: AGRICULTURA, PEC | E31: Médio | F31: ='03_FONTE_FAP'!F31 -> 35.6045 | G31: ='03_FONTE_FAP'!K31 -> 37.405 | H31: ='03_FONTE_FAP'!M31 -> 36.50475 | I31: ='01_PARÂMETROS'!$B$9 -> 50 | J31: =IFERROR(IF(H31=0,1,H31/I31),1) -> 0.730095 | K31: =MAX('01_PARÂMETROS'!$B$11,MIN('01_PARÂMETROS'!$B$12,J31)) -> 0.75 | L31: =(K31-1) -> -0.25 | M31: =IF(K31<='01_PARÂMETROS'!$B$14,"Preferencial",IF(K31<='01_PARÂMETROS'!$B$15,"Baixo",IF(K31<='01_PARÂMETROS'!$B$16,"Médio",IF(K31<='01_PARÂMETROS'!$B$17,"Alto","Elevado")))) -> Preferencial | N31: FAP/MPS
A32: 0131-8/00 | B32: A | C32: Cultivo de laranja | D32: AGRICULTURA, PEC | E32: Médio | F32: ='03_FONTE_FAP'!F32 -> 71.826 | G32: ='03_FONTE_FAP'!K32 -> 75.529 | H32: ='03_FONTE_FAP'!M32 -> 73.6775 | I32: ='01_PARÂMETROS'!$B$9 -> 50 | J32: =IFERROR(IF(H32=0,1,H32/I32),1) -> 1.47355 | K32: =MAX('01_PARÂMETROS'!$B$11,MIN('01_PARÂMETROS'!$B$12,J32)) -> 1.4 | L32: =(K32-1) -> 0.4 | M32: =IF(K32<='01_PARÂMETROS'!$B$14,"Preferencial",IF(K32<='01_PARÂMETROS'!$B$15,"Baixo",IF(K32<='01_PARÂMETROS'!$B$16,"Médio",IF(K32<='01_PARÂMETROS'!$B$17,"Alto","Elevado")))) -> Elevado | N32: FAP/MPS
A33: 0132-6/00 | B33: A | C33: Cultivo de uva | D33: AGRICULTURA, PEC | E33: Médio | F33: ='03_FONTE_FAP'!F33 -> 56.737 | G33: ='03_FONTE_FAP'!K33 -> 57.9025 | H33: ='03_FONTE_FAP'!M33 -> 57.31975 | I33: ='01_PARÂMETROS'!$B$9 -> 50 | J33: =IFERROR(IF(H33=0,1,H33/I33),1) -> 1.146395 | K33: =MAX('01_PARÂMETROS'!$B$11,MIN('01_PARÂMETROS'!$B$12,J33)) -> 1.146395 | L33: =(K33-1) -> 0.146395 | M33: =IF(K33<='01_PARÂMETROS'!$B$14,"Preferencial",IF(K33<='01_PARÂMETROS'!$B$15,"Baixo",IF(K33<='01_PARÂMETROS'!$B$16,"Médio",IF(K33<='01_PARÂMETROS'!$B$17,"Alto","Elevado")))) -> Alto | N33: FAP/MPS
A34: 0133-4/01 | B34: A | C34: Cultivo de açaí | D34: AGRICULTURA, PEC | E34: Médio | F34: ='03_FONTE_FAP'!F34 -> 26.84 | G34: ='03_FONTE_FAP'!K34 -> 46.0695 | H34: ='03_FONTE_FAP'!M34 -> 36.45475 | I34: ='01_PARÂMETROS'!$B$9 -> 50 | J34: =IFERROR(IF(H34=0,1,H34/I34),1) -> 0.729095 | K34: =MAX('01_PARÂMETROS'!$B$11,MIN('01_PARÂMETROS'!$B$12,J34)) -> 0.75 | L34: =(K34-1) -> -0.25 | M34: =IF(K34<='01_PARÂMETROS'!$B$14,"Preferencial",IF(K34<='01_PARÂMETROS'!$B$15,"Baixo",IF(K34<='01_PARÂMETROS'!$B$16,"Médio",IF(K34<='01_PARÂMETROS'!$B$17,"Alto","Elevado")))) -> Preferencial | N34: FAP/MPS | O34: Revisar
A35: 0133-4/02 | B35: A | C35: Cultivo de banana | D35: AGRICULTURA, PEC | E35: Médio | F35: ='03_FONTE_FAP'!F35 -> 62.6995 | G35: ='03_FONTE_FAP'!K35 -> 63.115 | H35: ='03_FONTE_FAP'!M35 -> 62.90725 | I35: ='01_PARÂMETROS'!$B$9 -> 50 | J35: =IFERROR(IF(H35=0,1,H35/I35),1) -> 1.258145 | K35: =MAX('01_PARÂMETROS'!$B$11,MIN('01_PARÂMETROS'!$B$12,J35)) -> 1.258145 | L35: =(K35-1) -> 0.258145 | M35: =IF(K35<='01_PARÂMETROS'!$B$14,"Preferencial",IF(K35<='01_PARÂMETROS'!$B$15,"Baixo",IF(K35<='01_PARÂMETROS'!$B$16,"Médio",IF(K35<='01_PARÂMETROS'!$B$17,"Alto","Elevado")))) -> Elevado | N35: FAP/MPS | O35: Revisar
A36: 0133-4/03 | B36: A | C36: Cultivo de caju | D36: AGRICULTURA, PEC | E36: Médio | F36: ='03_FONTE_FAP'!F36 -> 90.208 | G36: ='03_FONTE_FAP'!K36 -> 84.191 | H36: ='03_FONTE_FAP'!M36 -> 87.1995 | I36: ='01_PARÂMETROS'!$B$9 -> 50 | J36: =IFERROR(IF(H36=0,1,H36/I36),1) -> 1.74399 | K36: =MAX('01_PARÂMETROS'!$B$11,MIN('01_PARÂMETROS'!$B$12,J36)) -> 1.4 | L36: =(K36-1) -> 0.4 | M36: =IF(K36<='01_PARÂMETROS'!$B$14,"Preferencial",IF(K36<='01_PARÂMETROS'!$B$15,"Baixo",IF(K36<='01_PARÂMETROS'!$B$16,"Médio",IF(K36<='01_PARÂMETROS'!$B$17,"Alto","Elevado")))) -> Elevado | N36: FAP/MPS | O36: Revisar
A37: 0133-4/04 | B37: A | C37: Cultivo de cítricos, exceto laranja | D37: AGRICULTURA, PEC | E37: Médio | F37: ='03_FONTE_FAP'!F37 -> 37.166 | G37: ='03_FONTE_FAP'!K37 -> 40.2345 | H37: ='03_FONTE_FAP'!M37 -> 38.70025 | I37: ='01_PARÂMETROS'!$B$9 -> 50 | J37: =IFERROR(IF(H37=0,1,H37/I37),1) -> 0.774005 | K37: =MAX('01_PARÂMETROS'!$B$11,MIN('01_PARÂMETROS'!$B$12,J37)) -> 0.774005 | L37: =(K37-1) -> -0.225995 | M37: =IF(K37<='01_PARÂMETROS'!$B$14,"Preferencial",IF(K37<='01_PARÂMETROS'!$B$15,"Baixo",IF(K37<='01_PARÂMETROS'!$B$16,"Médio",IF(K37<='01_PARÂMETROS'!$B$17,"Alto","Elevado")))) -> Preferencial | N37: FAP/MPS | O37: Revisar
A38: 0133-4/05 | B38: A | C38: Cultivo de coco-da-baía | D38: AGRICULTURA, PEC | E38: Médio | F38: ='03_FONTE_FAP'!F38 -> 63.138 | G38: ='03_FONTE_FAP'!K38 -> 68.082 | H38: ='03_FONTE_FAP'!M38 -> 65.61 | I38: ='01_PARÂMETROS'!$B$9 -> 50 | J38: =IFERROR(IF(H38=0,1,H38/I38),1) -> 1.3122 | K38: =MAX('01_PARÂMETROS'!$B$11,MIN('01_PARÂMETROS'!$B$12,J38)) -> 1.3122 | L38: =(K38-1) -> 0.3122 | M38: =IF(K38<='01_PARÂMETROS'!$B$14,"Preferencial",IF(K38<='01_PARÂMETROS'!$B$15,"Baixo",IF(K38<='01_PARÂMETROS'!$B$16,"Médio",IF(K38<='01_PARÂMETROS'!$B$17,"Alto","Elevado")))) -> Elevado | N38: FAP/MPS | O38: Revisar
A39: 0133-4/06 | B39: A | C39: Cultivo de guaraná | D39: AGRICULTURA, PEC | E39: Médio | F39: — | G39: — | H39: — | I39: ='01_PARÂMETROS'!$B$9 -> 50 | J39: =1 -> 1 | K39: =MAX('01_PARÂMETROS'!$B$11,MIN('01_PARÂMETROS'!$B$12,J39)) -> 1 | L39: =(K39-1) -> 0 | M39: =IF(K39<='01_PARÂMETROS'!$B$14,"Preferencial",IF(K39<='01_PARÂMETROS'!$B$15,"Baixo",IF(K39<='01_PARÂMETROS'!$B$16,"Médio",IF(K39<='01_PARÂMETROS'!$B$17,"Alto","Elevado")))) -> Médio | N39: CNAE-STG
A40: 0133-4/07 | B40: A | C40: Cultivo de maçã | D40: AGRICULTURA, PEC | E40: Médio | F40: ='03_FONTE_FAP'!F40 -> 79.2735 | G40: ='03_FONTE_FAP'!K40 -> 55.328 | H40: ='03_FONTE_FAP'!M40 -> 67.30075 | I40: ='01_PARÂMETROS'!$B$9 -> 50 | J40: =IFERROR(IF(H40=0,1,H40/I40),1) -> 1.346015 | K40: =MAX('01_PARÂMETROS'!$B$11,MIN('01_PARÂMETROS'!$B$12,J40)) -> 1.346015 | L40: =(K40-1) -> 0.346015 | M40: =IF(K40<='01_PARÂMETROS'!$B$14,"Preferencial",IF(K40<='01_PARÂMETROS'!$B$15,"Baixo",IF(K40<='01_PARÂMETROS'!$B$16,"Médio",IF(K40<='01_PARÂMETROS'!$B$17,"Alto","Elevado")))) -> Elevado | N40: FAP/MPS | O40: Revisar
...

Sheet 05_TESTES_ADERÊNCIA
A1: TESTES DE ADERÊNCIA — VALIDA A METODOLOGIA DE RELATIVIDADES
A2: Todos os resultados são calculados por fórmula — referenciando 01_PARÂMETROS
A3: TESTE 1 — CONSISTÊNCIA INTERTEMPORAL (Correlação Spearman)
A4: Objetivo | B4: Verificar se os ICs de 2023 e 2024 são consistentes entre si
A5: H0 | B5: Correlação de Spearman ρ ≥ 0,70 (alta consistência)
A6: N subclasses com IC válido em ambos os anos | B6: 134
A7: ρ Spearman calculado (Python) | B7: 0.8414 | D7: ≥ 0,70 = aprovado
A8: Conclusão | B8: APROVADO — alta consistência intertemporal dos dados FAP
A9: Interpretação | B9: Rankings de risco por CNAE estáveis ano a ano. Valida uso da média 2023+2024 como estimativa robusta.
A11: TESTE 2 — HIPÓTESE SOBRE IC_ref = 50 (teste z bicaudal)
A12: H0 | B12: IC_ref = 50 é compatível com os dados (α = 5%)
A13: H1 | B13: IC_ref ≠ média observada (IC_ref não é a média dos dados)
A14: N observações (ICs válidos) | B14: ='01_PARÂMETROS'!B20 -> 280 | D14: Referência parâmetro E1
A15: IC Média observada | B15: ='01_PARÂMETROS'!B21 -> 54.25 | D15: Referência parâmetro E2
A16: IC Desvio Padrão | B16: ='01_PARÂMETROS'!B22 -> 24.2 | D16: Referência parâmetro E3
A17: Estatística z | B17: ='01_PARÂMETROS'!B29 -> 37.51141 | D17: Referência parâmetro F1 — calculada em 01_PARÂMETROS
A18: |z| > 1,96 (α=5%)? | B18: ='01_PARÂMETROS'!B30 -> NÃO — não rejeitar H0
A19: Interpretação | B19: O teste REJEITA H0 — IC_ref=50 não é a média dos dados FAP disponíveis (~54). ISSO É ESPERADO. IC_ref=50 é valor de referência teórico (mediana da escala), não estimativa da média. O viés de seleção dos PDFs (concentrados em setores de alto risco) justifica a escolha de IC_ref=50 em vez da média empírica.
A21: TESTE 3 — TRUNCAMENTO PELOS LIMITADORES
A22: Objetivo | B22: Avaliar se os limites 0,75 e 1,40 truncam excessivamente as relatividades
A23: N ICs calculados (total ambos os anos) | B23: 280
A24: N atingindo limite inferior 0.75 | B24: 76 | C24: 27.1% | D24: IC < 37,5
A25: N atingindo limite superior 1.4 | B25: 81 | C25: 28.9% | D25: IC > 70,0
A26: % truncado total | B26: 56.1%
A27: Conclusão | B27: ATENÇÃO — truncamento elevado (~40%). Indica alta dispersão dos dados FAP. Avaliar alargar limites (0,70–1,50) na próxima revisão.
A29: TESTE 4 — SENSIBILIDADE DO IC_ref (variar de 40 a 65)
A30: Objetivo | B30: Verificar se a distribuição das classes é sensível ao IC_ref adotado
A31: IC_ref testado | B31: % Preferencial | C31: % Elevado | D31: % Médio
A32: 40 | B32: 22% | C32: 57% | D32: 7%
A33: 45 | B33: 30% | C33: 50% | D33: 7%
A34: 50 | B34: 35% | C34: 41% | D34: 6%
A35: 55 | B35: 42% | C35: 30% | D35: 9%
A36: 60 | B36: 46% | C36: 24% | D36: 15%
A37: 65 | B37: 51% | C37: 19% | D37: 11%
A39: CONCLUSÃO GERAL
A40: Resumo | B40: (1) Consistência intertemporal FAP: APROVADA. (2) IC_ref=50 não é a média empírica — esperado e justificado. (3) Truncamento ~40% pelos limitadores: revisar limites na próxima atualização anual. (4) Sensibilidade ao IC_ref: distribuição pouco sensível entre 45-55 — metodologia robusta.

Sheet 06_AUDITORIA_CONSISTÊNCIA
A1: AUDITORIA DE CONSISTÊNCIA INTRA-DIVISÃO — RELATIVIDADES OPOSTAS
A2: Divisões CNAE com subclasses de classes opostas (desagravo ↔ agravo). Total: 21 divisões. Revise os sinalizados como 'Anomalia'.
A3: Divisão | B3: CNAE | C3: Descrição Subclasse | D3: IC Médio | E3: Relat. Final | F3: Classe | G3: Ajuste % | H3: Justificativa | I3: Classificação
A4: DIVISÃO 01.11 — AGRICULTURA, PECUÁRIA E SERVIÇOS RELACIONADOS
A5: 01.11 | B5: 01.11-3/03 | C5: Cultivo de trigo | D5: 22.99 | E5: 0.75 | F5: Preferencial | G5: -0.25 | H5: Subclasses com perfis distintos dentro da mesma divisão | I5: Aceitável
A6: 01.11 | B6: 01.11-3/02 | C6: Cultivo de milho | D6: 38.42 | E6: 0.7684 | F6: Preferencial | G6: -0.2316 | H6: Subclasses com perfis distintos dentro da mesma divisão | I6: Aceitável
A7: 01.11 | B7: 01.11-3/01 | C7: Cultivo de arroz | D7: 56.13 | E7: 1.1226 | F7: Alto | G7: 0.1226 | H7: Subclasses com perfis distintos dentro da mesma divisão | I7: Aceitável
A8: 01.11 | B8: 01.11-3/99 | C8: Cultivo de outros cereais não especificados anteriormente | D8: 58.21 | E8: 1.1642 | F8: Alto | G8: 0.1642 | H8: Subclasses com perfis distintos dentro da mesma divisão | I8: Aceitável
A10: DIVISÃO 01.12 — AGRICULTURA, PECUÁRIA E SERVIÇOS RELACIONADOS
A11: 01.12 | B11: 01.12-1/02 | C11: Cultivo de juta | D11: 36.83 | E11: 0.75 | F11: Preferencial | G11: -0.25 | H11: Subclasses com perfis distintos dentro da mesma divisão | I11: Aceitável
A12: 01.12 | B12: 01.12-1/01 | C12: Cultivo de algodão herbáceo | D12: 54.89 | E12: 1.0978 | F12: Alto | G12: 0.0978 | H12: Subclasses com perfis distintos dentro da mesma divisão | I12: Aceitável
A14: DIVISÃO 01.19 — AGRICULTURA, PECUÁRIA E SERVIÇOS RELACIONADOS
A15: 01.19 | B15: 01.19-9/02 | C15: Cultivo de alho | D15: 19.55 | E15: 0.75 | F15: Preferencial | G15: -0.25 | H15: Subclasses com perfis distintos dentro da mesma divisão | I15: Aceitável
A16: 01.19 | B16: 01.19-9/04 | C16: Cultivo de cebola | D16: 19.94 | E16: 0.75 | F16: Preferencial | G16: -0.25 | H16: Subclasses com perfis distintos dentro da mesma divisão | I16: Aceitável
A17: 01.19 | B17: 01.19-9/06 | C17: Cultivo de mandioca | D17: 12.98 | E17: 0.75 | F17: Preferencial | G17: -0.25 | H17: Subclasses com perfis distintos dentro da mesma divisão | I17: Aceitável
A18: 01.19 | B18: 01.19-9/09 | C18: Cultivo de tomate rasteiro | D18: 11.72 | E18: 0.75 | F18: Preferencial | G18: -0.25 | H18: Subclasses com perfis distintos dentro da mesma divisão | I18: Aceitável
A19: 01.19 | B19: 01.19-9/05 | C19: Cultivo de feijão | D19: 46.22 | E19: 0.9244 | F19: Baixo | G19: -0.0756 | H19: Subclasses com perfis distintos dentro da mesma divisão | I19: Aceitável
A20: 01.19 | B20: 01.19-9/07 | C20: Cultivo de melão | D20: 50.88 | E20: 1.0176 | F20: Médio | G20: 0.0176 | H20: Subclasses com perfis distintos dentro da mesma divisão | I20: Aceitável
A21: 01.19 | B21: 01.19-9/03 | C21: Cultivo de batata-inglesa | D21: 57.81 | E21: 1.1562 | F21: Alto | G21: 0.1562 | H21: Subclasses com perfis distintos dentro da mesma divisão | I21: Aceitável
A22: 01.19 | B22: 01.19-9/99 | C22: Cultivo de outras plantas de lavoura temporária não especificadas anteriormente | D22: 64.35 | E22: 1.287 | F22: Elevado | G22: 0.287 | H22: Subclasses com perfis distintos dentro da mesma divisão | I22: Aceitável
A24: DIVISÃO 01.33 — AGRICULTURA, PECUÁRIA E SERVIÇOS RELACIONADOS
A25: 01.33 | B25: 01.33-4/01 | C25: Cultivo de açaí | D25: 36.45 | E25: 0.75 | F25: Preferencial | G25: -0.25 | H25: Extremo inferior vs extremo superior na mesma divisão — verificar contexto | I25: Revisar
A26: 01.33 | B26: 01.33-4/10 | C26: Cultivo de manga | D26: 38.26 | E26: 0.7652 | F26: Preferencial | G26: -0.2348 | H26: Subclasses com perfis distintos dentro da mesma divisão | I26: Aceitável
A27: 01.33 | B27: 01.33-4/04 | C27: Cultivo de cítricos, exceto laranja | D27: 38.7 | E27: 0.774 | F27: Preferencial | G27: -0.226 | H27: Subclasses com perfis distintos dentro da mesma divisão | I27: Aceitável
A28: 01.33 | B28: 01.33-4/09 | C28: Cultivo de maracujá | D28: 38.84 | E28: 0.7768 | F28: Preferencial | G28: -0.2232 | H28: Subclasses com perfis distintos dentro da mesma divisão | I28: Aceitável
A29: 01.33 | B29: 01.33-4/99 | C29: Cultivo de frutas de lavoura permanente não especificadas anteriormente | D29: 47.3 | E29: 0.946 | F29: Baixo | G29: -0.054 | H29: Subclasses com perfis distintos dentro da mesma divisão | I29: Aceitável
A30: 01.33 | B30: 01.33-4/08 | C30: Cultivo de mamão | D30: 56.39 | E30: 1.1278 | F30: Alto | G30: 0.1278 | H30: Subclasses com perfis distintos dentro da mesma divisão | I30: Aceitável
A31: 01.33 | B31: 01.33-4/02 | C31: Cultivo de banana | D31: 62.91 | E31: 1.2582 | F31: Elevado | G31: 0.2582 | H31: Subclasses com perfis distintos dentro da mesma divisão | I31: Aceitável
A32: 01.33 | B32: 01.33-4/05 | C32: Cultivo de coco-da-baía | D32: 65.61 | E32: 1.3122 | F32: Elevado | G32: 0.3122 | H32: Subclasses com perfis distintos dentro da mesma divisão | I32: Aceitável
A33: 01.33 | B33: 01.33-4/07 | C33: Cultivo de maçã | D33: 67.3 | E33: 1.346 | F33: Elevado | G33: 0.346 | H33: Subclasses com perfis distintos dentro da mesma divisão | I33: Aceitável
A34: 01.33 | B34: 01.33-4/03 | C34: Cultivo de caju | D34: 87.2 | E34: 1.4 | F34: Elevado | G34: 0.4 | H34: Subclasses com perfis distintos dentro da mesma divisão | I34: Aceitável
A36: DIVISÃO 01.39 — AGRICULTURA, PECUÁRIA E SERVIÇOS RELACIONADOS
A37: 01.39 | B37: 01.39-3/04 | C37: Cultivo de plantas para condimento, exceto pimenta-do-reino | D37: 28.54 | E37: 0.75 | F37: Preferencial | G37: -0.25 | H37: Extremo inferior vs extremo superior na mesma divisão — verificar contexto | I37: Revisar
A38: 01.39 | B38: 01.39-3/06 | C38: Cultivo de seringueira | D38: 15.46 | E38: 0.75 | F38: Preferencial | G38: -0.25 | H38: Extremo inferior vs extremo superior na mesma divisão — verificar contexto | I38: Revisar
A39: 01.39 | B39: 01.39-3/02 | C39: Cultivo de erva-mate | D39: 44.55 | E39: 0.891 | F39: Baixo | G39: -0.109 | H39: Subclasses com perfis distintos dentro da mesma divisão | I39: Aceitável
A40: 01.39 | B40: 01.39-3/99 | C40: Cultivo de outras plantas de lavoura permanente não especificadas anteriormente | D40: 55.61 | E40: 1.1122 | F40: Alto | G40: 0.1122 | H40: Subclasses com perfis distintos dentro da mesma divisão | I40: Aceitável
A41: 01.39 | B41: 01.39-3/05 | C41: Cultivo de dendê | D41: 69.86 | E41: 1.3972 | F41: Elevado | G41: 0.3972 | H41: Subclasses com perfis distintos dentro da mesma divisão | I41: Aceitável
A42: 01.39 | B42: 01.39-3/03 | C42: Cultivo de pimenta-do-reino | D42: 76.65 | E42: 1.4 | F42: Elevado | G42: 0.4 | H42: Subclasses com perfis distintos dentro da mesma divisão | I42: Aceitável
A44: DIVISÃO 01.41 — AGRICULTURA, PECUÁRIA E SERVIÇOS RELACIONADOS
A45: 01.41 | B45: 01.41-5/01 | C45: Produção de sementes certificadas, exceto de forrageiras para pasto | D45: 34.28 | E45: 0.75 | F45: Preferencial | G45: -0.25 | H45: Extremo inferior vs extremo superior na mesma divisão — verificar contexto | I45: Revisar
...

Sheet 07_CONSULTA_CNAE
A1: CONSULTA RÁPIDA — CNAE: DADOS FAP E RELATIVIDADES
A2: Digite o código no campo azul abaixo (formato: 0000-0/00). Todos os campos atualizam automaticamente via fórmula.
A5: ▼ DIGITE O CÓDIGO CNAE (ex: 0111-3/01 ou 0500-3/01 ou 0810-0/01)
A6: 0111-3/01
A8: IDENTIFICAÇÃO
A9: CNAE | B9: =IFERROR(INDEX('04_MOTOR_CÁLCULO'!A:A,MATCH($A$6,'04_MOTOR_CÁLCULO'!$A:$A,0)),"Código não encontrado") -> 0111-3/01
A10: Seção | B10: =IFERROR(INDEX('04_MOTOR_CÁLCULO'!B:B,MATCH($A$6,'04_MOTOR_CÁLCULO'!$A:$A,0)),"Código não encontrado") -> A
A11: Descrição | B11: =IFERROR(INDEX('04_MOTOR_CÁLCULO'!C:C,MATCH($A$6,'04_MOTOR_CÁLCULO'!$A:$A,0)),"Código não encontrado") -> Cultivo de arroz
A12: Classificação CNAE-STG | B12: =IFERROR(INDEX('04_MOTOR_CÁLCULO'!E:E,MATCH($A$6,'04_MOTOR_CÁLCULO'!$A:$A,0)),"Código não encontrado") -> Médio
A14: DADOS FAP — PERCENTIS BRUTOS
A15: P_Frequência 2023 | B15: =IFERROR(INDEX('03_FONTE_FAP'!C:C,MATCH($A$6,'03_FONTE_FAP'!$A:$A,0)),"N/D") -> N/D | C15: Vigência 2024 — período-base 2021-2022
A16: P_Gravidade 2023 | B16: =IFERROR(INDEX('03_FONTE_FAP'!D:D,MATCH($A$6,'03_FONTE_FAP'!$A:$A,0)),"N/D") -> N/D
A17: P_Custo 2023 | B17: =IFERROR(INDEX('03_FONTE_FAP'!E:E,MATCH($A$6,'03_FONTE_FAP'!$A:$A,0)),"N/D") -> N/D
A18: P_Frequência 2024 | B18: =IFERROR(INDEX('03_FONTE_FAP'!H:H,MATCH($A$6,'03_FONTE_FAP'!$A:$A,0)),"N/D") -> N/D | C18: Vigência 2025 — período-base 2022-2023
A19: P_Gravidade 2024 | B19: =IFERROR(INDEX('03_FONTE_FAP'!I:I,MATCH($A$6,'03_FONTE_FAP'!$A:$A,0)),"N/D") -> N/D
A20: P_Custo 2024 | B20: =IFERROR(INDEX('03_FONTE_FAP'!J:J,MATCH($A$6,'03_FONTE_FAP'!$A:$A,0)),"N/D") -> N/D
A22: ÍNDICE COMPOSTO — CALCULADO POR FÓRMULA
A23: IC 2023 [= w_G×P_Grav + w_F×P_Freq + w_C×P_Custo] | B23: =IFERROR(INDEX('03_FONTE_FAP'!F:F,MATCH($A$6,'03_FONTE_FAP'!$A:$A,0)),"N/D") -> N/D
A24: IC 2024 | B24: =IFERROR(INDEX('03_FONTE_FAP'!K:K,MATCH($A$6,'03_FONTE_FAP'!$A:$A,0)),"N/D") -> N/D
A25: IC Médio | B25: =IFERROR(INDEX('03_FONTE_FAP'!M:M,MATCH($A$6,'03_FONTE_FAP'!$A:$A,0)),"N/D") -> N/D | C25: Média dos ICs válidos disponíveis
A26: IC Referência (parâmetro B1) | B26: ='01_PARÂMETROS'!$B$9 -> 50 | C26: Fixo = 50,0 (mediana teórica)
A28: RELATIVIDADE FINAL
A29: Relatividade Bruta [= IC_Médio / IC_ref] | B29: =IFERROR(INDEX('03_FONTE_FAP'!N:N,MATCH($A$6,'03_FONTE_FAP'!$A:$A,0)),"N/D") -> N/D
A30: Relatividade Final [= MAX(0,75 ; MIN(1,40 ; Bruta)) | B30: =IFERROR(INDEX('04_MOTOR_CÁLCULO'!K:K,MATCH($A$6,'04_MOTOR_CÁLCULO'!$A:$A,0)),"Código não encontrado") -> 1.12263
A31: Ajuste sobre a Taxa Pura | B31: =IFERROR(INDEX('04_MOTOR_CÁLCULO'!L:L,MATCH($A$6,'04_MOTOR_CÁLCULO'!$A:$A,0)),"Código não encontrado") -> 0.12263
A32: Classe de Risco | B32: =IFERROR(INDEX('04_MOTOR_CÁLCULO'!M:M,MATCH($A$6,'04_MOTOR_CÁLCULO'!$A:$A,0)),"Código não encontrado") -> Alto
